Workbook

Sheet qPCR.primers.iNeurons
A1: Primer | B1: Sequence (5'-3')
A2: eGFP-Fwd | B2: AGTCCGCCCTGAGCAAAGA
A3: eGFP-Rev | B3: TCCAGCAGGACCATGTGATC
A4: mNGN2-Fwd | B4: AGACGGTGCAGCGCATCAAGAA
A5: mNGN2-Rev | B5: AGCGTCTCGATCTTCGTGAGCT
A6: BRN2-Fwd | B6: ACCCGCTTTATCGAAGGCAA
A7: BRN2-Rev | B7: CCTCCATAACCTCCCCCAGA
A8: ISL1-Fwd | B8: AAGGTGGAGCTGCATTGGTTTG
A9: ISL1-Rev | B9: TAAACCAGCTACAGGACAGGCC
A10: Nestin-Fwd | B10: ACCCGCTTTATCGAAGGCAA
A11: Nestin-Rev | B11: AAGCTGAGGGAAGTCTTGGAGC
A12: MAP2-Fwd | B12: AGACTGCAGCTCTGCCTTTAG
... A23: RPL37A-Rev | B23: TTCTGATGGCGGACTTTACCG

Sheet qPCR-raw-data
A1: Experiment: 2025.04.09-DSP-GallowayLab.iN.qPCR Selected Filter: SYBR Green I / HRM Dye (465-510)
A2: TRUE | B2: 255 | C2: A1 | D2: 1 | E2: 23.09 | G2: 0
A3: TRUE | B3: 255 | C3: A2 | D3: 2 | E3: 23.52 | G3: 0
A4: TRUE | B4: 255 | C4: A3 | D4: 3 | E4: 23.18 | G4: 0
A5: TRUE | B5: 255 | C5: A4 | D5: 4 | E5: 22.81 | G5: 0
A6: TRUE | B6: 255 | C6: A5 | D6: 5 | E6: 22.92 | G6: 0
A7: TRUE | B7: 255 | C7: A6 | D7: 6 | E7: 22.88 | G7: 0
A8: TRUE | B8: 255 | C8: A7 | D8: 7 | E8: 23.12 | G8: 0
A9: TRUE | B9: 255 | C9: A8 | D9: 8 | E9: 23.61 | G9: 0
A10: TRUE | B10: 255 | C10: A9 | D10: 9 | E10: 23.74 | G10: 0
A11: TRUE | B11: 255 | C11: A10 | D11: 10 | E11: 23.36 | G11: 0
A12: TRUE | B12: 255 | C12: A11 | D12: 11 | E12: 23.87 | G12: 0
A13: TRUE | B13: 255 | C13: A12 | D13: 12 | E13: 23.87 | G13: 0
... A19: TRUE | B19: 255 | C19: A18 | D19: 18 | E19: 24.91 | G19: 0
A20: TRUE | B20: 65280 | C20: A19 | D20: 19 | G20: 0
A21: TRUE | B21: 65280 | C21: A20 | D21: 20 | G21: 0
A22: TRUE | B22: 65280 | C22: A21 | D22: 21 | G22: 0
A23: TRUE | B23: 65280 | C23: A22 | D23: 22 | G23: 0
A24: TRUE | B24: 65280 | C24: A23 | D24: 23 | G24: 0
A25: TRUE | B25: 65280 | C25: A24 | D25: 24 | G25: 0
A26: TRUE | B26: 255 | C26: B1 | D26: 25 | E26: 22.21 | G26: 0
A27: TRUE | B27: 255 | C27: B2 | D27: 26 | E27: 22.13 | G27: 0
A28: TRUE | B28: 255 | C28: B3 | D28: 27 | E28: 22.37 | G28: 0
A29: TRUE | B29: 255 | C29: B4 | D29: 28 | E29: 21.77 | G29: 0
A30: TRUE | B30: 255 | C30: B5 | D30: 29 | E30: 21.8 | G30: 0
A31: TRUE | B31: 255 | C31: B6 | D31: 30 | E31: 21.81 | G31: 0
A32: TRUE | B32: 255 | C32: B7 | D32: 31 | E32: 22.33 | G32: 0
A33: TRUE | B33: 255 | C33: B8 | D33: 32 | E33: 22.46 | G33: 0
A34: TRUE | B34: 255 | C34: B9 | D34: 33 | E34: 22.5 | G34: 0
A35: TRUE | B35: 255 | C35: B10 | D35: 34 | E35: 22.29 | G35: 0
A36: TRUE | B36: 255 | C36: B11 | D36: 35 | E36: 22.47 | G36: 0
A37: TRUE | B37: 255 | C37: B12 | D37: 36 | E37: 22.52 | G37: 0
... A43: TRUE | B43: 255 | C43: B18 | D43: 42 | E43: 23.33 | G43: 0
A44: TRUE | B44: 65280 | C44: B19 | D44: 43 | G44: 0
A45: TRUE | B45: 65280 | C45: B20 | D45: 44 | G45: 0
A46: TRUE | B46: 65280 | C46: B21 | D46: 45 | G46: 0
A47: TRUE | B47: 65280 | C47: B22 | D47: 46 | G47: 0
A48: TRUE | B48: 65280 | C48: B23 | D48: 47 | G48: 0
A49: TRUE | B49: 65280 | C49: B24 | D49: 48 | G49: 0
A50: TRUE | B50: 255 | C50: C1 | D50: 49 | E50: 22.22 | G50: 0
...

Sheet plate.layout.raw.Ct.values
C1: iN-1a | D1: iN-1b | E1: iN-1c | F1: iN-2a | G1: iN-2b | H1: iN-2c | I1: iN-3a | J1: iN-3b | K1: iN-3c | L1: iPSC-1a | M1: iPSC-1b | N1: iPSC-1c | O1: iPSC-2a | P1: iPSC-2b | Q1: iPSC-2c | R1: iPSC-3a | S1: iPSC-3b | T1: iPSC-3c
C2: 1 | D2: 2 | E2: 3 | F2: 4 | G2: 5 | H2: 6 | I2: 7 | J2: 8 | K2: 9 | L2: 10 | M2: 11 | N2: 12 | O2: 13 | P2: 14 | Q2: 15 | R2: 16 | S2: 17 | T2: 18
A4: eGFP-2 | B4: B | C4: 22.21 | D4: 22.13 | E4: 22.37 | F4: 21.77 | G4: 21.8 | H4: 21.81 | I4: 22.33 | J4: 22.46 | K4: 22.5 | L4: 22.29 | M4: 22.47 | N4: 22.52 | O4: 22.68 | P4: 22.8 | Q4: 22.78 | R4: 23.23 | S4: 23.26 | T4: 23.33
A5: mNgn2 | B5: C | C5: 22.22 | D5: 22.17 | E5: 22.14 | F5: 22.14 | G5: 21.95 | H5: 21.95 | I5: 22.51 | J5: 22.47 | K5: 22.58 | L5: 33.8 | M5: 34.24 | N5: 34.17 | O5: 33.89 | P5: 35 | Q5: 33.16 | R5: 32.81 | S5: 33.84 | T5: 32.55
A6: BRN2 | B6: E | C6: 30.58 | D6: 31.67 | E6: 30.95 | F6: 29.89 | G6: 29.89 | H6: 29.96 | I6: 29.82 | J6: 29.94 | K6: 29.74 | L6: 33 | M6: 32.71 | N6: 32.78 | O6: 33.89 | P6: 35.11 | Q6: 37.89 | R6: 33.18 | S6: 34.14 | T6: 34.81
A7: ISL1 | B7: F | C7: 26.71 | D7: 26.93 | E7: 26.94 | F7: 26.26 | G7: 25.88 | H7: 26.43 | I7: 25.67 | J7: 25.64 | K7: 25.89 | L7: 29.31 | M7: 29.48 | N7: 29.42 | O7: 29.54 | P7: 29.64 | Q7: 29.06 | R7: 30.68 | S7: 30.19 | T7: 30.5
A8: Nestin | B8: G | C8: 28.71 | D8: 28.53 | E8: 28.67 | F8: 27.68 | G8: 27.61 | H8: 27.84 | I8: 28.16 | J8: 27.89 | K8: 27.85 | L8: 27.93 | M8: 28.02 | N8: 28.08 | O8: 29.5 | P8: 29.25 | Q8: 29.2 | R8: 29.25 | S8: 29.5 | T8: 29.42
A9: MAP2 | B9: H | C9: 32.57 | D9: 32.3 | E9: 32.86 | F9: 31.48 | G9: 31.49 | H9: 31.14 | I9: 30.97 | J9: 31.58 | K9: 31.02 | L9: 33.59 | M9: 33.09 | N9: 33.53 | O9: 40 | P9: 34.82 | Q9: 34.88 | R9: 36.65 | S9: 35.74 | T9: 36.08
A10: TUBB3 | B10: I | C10: 26.01 | D10: 25.98 | E10: 25.98 | F10: 25.68 | G10: 25.64 | H10: 25.68 | I10: 25.24 | J10: 25.34 | K10: 25.34 | L10: 27.12 | M10: 27.03 | N10: 27.04 | O10: 28.22 | P10: 28.52 | Q10: 28.46 | R10: 28.76 | S10: 29.16 | T10: 28.93
A11: GRIA4 | B11: J | C11: 31.87 | D11: 32.62 | E11: 31.49 | F11: 31 | G11: 31.55 | H11: 31.06 | I11: 31.05 | J11: 31.16 | K11: 31.17 | L11: 31.51 | M11: 31.22 | N11: 31.26 | O11: 33.17 | P11: 32.58 | Q11: 33.52 | R11: 33.57 | S11: 34.53 | T11: 34.51
A12: SYP | B12: K | C12: 30.91 | D12: 31.15 | E12: 31.14 | F12: 30.9 | G12: 30.94 | H12: 30.89 | I12: 30.88 | J12: 29.84 | K12: 31.02 | L12: 32.28 | M12: 32.13 | N12: 33.02 | O12: 32.68 | P12: 32.74 | Q12: 32.44 | R12: 32.63 | S12: 32.72 | T12: 32.16
A13: VGLUT2 | B13: L | C13: 29.59 | D13: 29.27 | E13: 29.63 | F13: 28.63 | G13: 28.63 | H13: 28.68 | I13: 28.28 | J13: 29.75 | K13: 28.14 | L13: 37.02 | M13: 38.26 | N13: 39.12 | P13: 37.02 | Q13: 40 | R13: 36.64 | S13: 40 | T13: 40
A14: RPL47A | B14: M | C14: 23.3 | D14: 23.13 | E14: 23.19 | F14: 23.35 | G14: 23.25 | H14: 23.19 | I14: 22.51 | J14: 22.58 | K14: 22.54 | L14: 19.69 | M14: 19.9 | N14: 19.76 | O14: 21.47 | P14: 21.49 | Q14: 21.43 | R14: 23.02 | S14: 23.07 | T14: 23.34

Sheet qPCR.analyzed
C2: iN-1 | D2: iN-2 | E2: iN-3 | F2: iNs | J2: iPSC-1 | K2: iPSC-2 | L2: iPSC-3 | M2: iPSCs
C3: Mean Ct tech reps | F3: mean Ct | G3: deltaCt | H3: 2^(-deltaCt) | I3: log10(2^(-deltaCt)) | J3: Mean Ct tech reps | M3: mean Ct | N3: deltaCt | O3: 2^(-deltaCt) | P3: log10(2^(-deltaCt))
A4: eGFP-2 | B4: B | C4: =AVERAGE('plate.layout.raw.Ct.values'!C4:E4) -> 22.236667 | D4: =AVERAGE('plate.layout.raw.Ct.values'!F4:H4) -> 21.793333 | E4: =AVERAGE('plate.layout.raw.Ct.values'!I4:K4) -> 22.43 | F4: =AVERAGE(C4:E4) -> 22.153333 | G4: =F4-$F$14 -> -0.85111111 | H4: =2^(-G4) -> 1.8038897 | I4: =LOG(H4) -> 0.25620997 | J4: =AVERAGE('plate.layout.raw.Ct.values'!L4:N4) -> 22.426667 | K4: =AVERAGE('plate.layout.raw.Ct.values'!O4:Q4) -> 22.753333 | L4: =AVERAGE('plate.layout.raw.Ct.values'!R4:T4) -> 23.273333 | M4: =AVERAGE(J4:L4) -> 22.817778 | N4: =M4-$M$14 -> 1.3544444 | O4: =2^(-N4) -> 0.39108539 | P4: =LOG(O4) -> -0.40772841
A5: mNgn2 | B5: C | C5: =AVERAGE('plate.layout.raw.Ct.values'!C5:E5) -> 22.176667 | D5: =AVERAGE('plate.layout.raw.Ct.values'!F5:H5) -> 22.013333 | E5: =AVERAGE('plate.layout.raw.Ct.values'!I5:K5) -> 22.52 | F5: =AVERAGE(C5:E5) -> 22.236667 | G5: =F5-$F$14 -> -0.76777778 | H5: =2^(-G5) -> 1.7026451 | I5: =LOG(H5) -> 0.23112414 | J5: =AVERAGE('plate.layout.raw.Ct.values'!L5:N5) -> 34.07 | K5: =AVERAGE('plate.layout.raw.Ct.values'!O5:Q5) -> 34.016667 | L5: =AVERAGE('plate.layout.raw.Ct.values'!R5:T5) -> 33.066667 | M5: =AVERAGE(J5:L5) -> 33.717778 | N5: =M5-$M$14 -> 12.254444 | O5: =2^(-N5) -> 0.0002046655 | P5: =LOG(O5) -> -3.6889554
A6: BRN2 | B6: E | C6: =AVERAGE('plate.layout.raw.Ct.values'!C6:E6) -> 31.066667 | D6: =AVERAGE('plate.layout.raw.Ct.values'!F6:H6) -> 29.913333 | E6: =AVERAGE('plate.layout.raw.Ct.values'!I6:K6) -> 29.833333 | F6: =AVERAGE(C6:E6) -> 30.271111 | G6: =F6-$F$14 -> 7.2666667 | H6: =2^(-G6) -> 0.0064940461 | I6: =LOG(H6) -> -2.1874846 | J6: =AVERAGE('plate.layout.raw.Ct.values'!L6:N6) -> 32.83 | K6: =AVERAGE('plate.layout.raw.Ct.values'!O6:Q6) -> 35.63 | L6: =AVERAGE('plate.layout.raw.Ct.values'!R6:T6) -> 34.043333 | M6: =AVERAGE(J6:L6) -> 34.167778 | N6: =M6-$M$14 -> 12.704444 | O6: =2^(-N6) -> 0.00014982392 | P6: =LOG(O6) -> -3.8244189
A7: ISL1 | B7: F | C7: =AVERAGE('plate.layout.raw.Ct.values'!C7:E7) -> 26.86 | D7: =AVERAGE('plate.layout.raw.Ct.values'!F7:H7) -> 26.19 | E7: =AVERAGE('plate.layout.raw.Ct.values'!I7:K7) -> 25.733333 | F7: =AVERAGE(C7:E7) -> 26.261111 | G7: =F7-$F$14 -> 3.2566667 | H7: =2^(-G7) -> 0.10462745 | I7: =LOG(H7) -> -0.98035435 | J7: =AVERAGE('plate.layout.raw.Ct.values'!L7:N7) -> 29.403333 | K7: =AVERAGE('plate.layout.raw.Ct.values'!O7:Q7) -> 29.413333 | L7: =AVERAGE('plate.layout.raw.Ct.values'!R7:T7) -> 30.456667 | M7: =AVERAGE(J7:L7) -> 29.757778 | N7: =M7-$M$14 -> 8.2944444 | O7: =2^(-N7) -> 0.0031851026 | P7: =LOG(O7) -> -2.4968766
A8: Nestin | B8: G | C8: =AVERAGE('plate.layout.raw.Ct.values'!C8:E8) -> 28.636667 | D8: =AVERAGE('plate.layout.raw.Ct.values'!F8:H8) -> 27.71 | E8: =AVERAGE('plate.layout.raw.Ct.values'!I8:K8) -> 27.966667 | F8: =AVERAGE(C8:E8) -> 28.104444 | G8: =F8-$F$14 -> 5.1 | H8: =2^(-G8) -> 0.029157281 | I8: =LOG(H8) -> -1.535253 | J8: =AVERAGE('plate.layout.raw.Ct.values'!L8:N8) -> 28.01 | K8: =AVERAGE('plate.layout.raw.Ct.values'!O8:Q8) -> 29.316667 | L8: =AVERAGE('plate.layout.raw.Ct.values'!R8:T8) -> 29.39 | M8: =AVERAGE(J8:L8) -> 28.905556 | N8: =M8-$M$14 -> 7.4422222 | O8: =2^(-N8) -> 0.0057500004 | P8: =LOG(O8) -> -2.2403321
A9: MAP2 | B9: H | C9: =AVERAGE('plate.layout.raw.Ct.values'!C9:E9) -> 32.576667 | D9: =AVERAGE('plate.layout.raw.Ct.values'!F9:H9) -> 31.37 | E9: =AVERAGE('plate.layout.raw.Ct.values'!I9:K9) -> 31.19 | F9: =AVERAGE(C9:E9) -> 31.712222 | G9: =F9-$F$14 -> 8.7077778 | H9: =2^(-G9) -> 0.0023916504 | I9: =LOG(H9) -> -2.6213023 | J9: =AVERAGE('plate.layout.raw.Ct.values'!L9:N9) -> 33.403333 | K9: =AVERAGE('plate.layout.raw.Ct.values'!O9:Q9) -> 36.566667 | L9: =AVERAGE('plate.layout.raw.Ct.values'!R9:T9) -> 36.156667 | M9: =AVERAGE(J9:L9) -> 35.375556 | N9: =M9-$M$14 -> 13.912222 | O9: =2^(-N9) -> 6.4864012e-05 | P9: =LOG(O9) -> -4.1879962
A10: TUBB3 | B10: I | C10: =AVERAGE('plate.layout.raw.Ct.values'!C10:E10) -> 25.99 | D10: =AVERAGE('plate.layout.raw.Ct.values'!F10:H10) -> 25.666667 | E10: =AVERAGE('plate.layout.raw.Ct.values'!I10:K10) -> 25.306667 | F10: =AVERAGE(C10:E10) -> 25.654444 | G10: =F10-$F$14 -> 2.65 | H10: =2^(-G10) -> 0.15932008 | I10: =LOG(H10) -> -0.79772949 | J10: =AVERAGE('plate.layout.raw.Ct.values'!L10:N10) -> 27.063333 | K10: =AVERAGE('plate.layout.raw.Ct.values'!O10:Q10) -> 28.4 | L10: =AVERAGE('plate.layout.raw.Ct.values'!R10:T10) -> 28.95 | M10: =AVERAGE(J10:L10) -> 28.137778 | N10: =M10-$M$14 -> 6.6744444 | O10: =2^(-N10) -> 0.0097902102 | P10: =LOG(O10) -> -2.009208
A11: GRIA4 | B11: J | C11: =AVERAGE('plate.layout.raw.Ct.values'!C11:E11) -> 31.993333 | D11: =AVERAGE('plate.layout.raw.Ct.values'!F11:H11) -> 31.203333 | E11: =AVERAGE('plate.layout.raw.Ct.values'!I11:K11) -> 31.126667 | F11: =AVERAGE(C11:E11) -> 31.441111 | G11: =F11-$F$14 -> 8.4366667 | H11: =2^(-G11) -> 0.0028860927 | I11: =LOG(H11) -> -2.5396897 | J11: =AVERAGE('plate.layout.raw.Ct.values'!L11:N11) -> 31.33 | K11: =AVERAGE('plate.layout.raw.Ct.values'!O11:Q11) -> 33.09 | L11: =AVERAGE('plate.layout.raw.Ct.values'!R11:T11) -> 34.203333 | M11: =AVERAGE(J11:L11) -> 32.874444 | N11: =M11-$M$14 -> 11.411111 | O11: =2^(-N11) -> 0.00036720896 | P11: =LOG(O11) -> -3.4350867
A12: SYP | B12: K | C12: =AVERAGE('plate.layout.raw.Ct.values'!C12:E12) -> 31.066667 | D12: =AVERAGE('plate.layout.raw.Ct.values'!F12:H12) -> 30.91 | E12: =AVERAGE('plate.layout.raw.Ct.values'!I12:K12) -> 30.58 | F12: =AVERAGE(C12:E12) -> 30.852222 | G12: =F12-$F$14 -> 7.8477778 | H12: =2^(-G12) -> 0.0043409371 | I12: =LOG(H12) -> -2.3624165 | J12: =AVERAGE('plate.layout.raw.Ct.values'!L12:N12) -> 32.476667 | K12: =AVERAGE('plate.layout.raw.Ct.values'!O12:Q12) -> 32.62 | L12: =AVERAGE('plate.layout.raw.Ct.values'!R12:T12) -> 32.503333 | M12: =AVERAGE(J12:L12) -> 32.533333 | N12: =M12-$M$14 -> 11.07 | O12: =2^(-N12) -> 0.00046515527 | P12: =LOG(O12) -> -3.3324021
A13: VGLUT2 | B13: L | C13: =AVERAGE('plate.layout.raw.Ct.values'!C13:E13) -> 29.496667 | D13: =AVERAGE('plate.layout.raw.Ct.values'!F13:H13) -> 28.646667 | E13: =AVERAGE('plate.layout.raw.Ct.values'!I13:K13) -> 28.723333 | F13: =AVERAGE(C13:E13) -> 28.955556 | G13: =F13-$F$14 -> 5.9511111 | H13: =2^(-G13) -> 0.016163561 | I13: =LOG(H13) -> -1.791463 | J13: =AVERAGE('plate.layout.raw.Ct.values'!L13:N13) -> 38.133333 | K13: =AVERAGE('plate.layout.raw.Ct.values'!O13:Q13) -> 38.51 | L13: =AVERAGE('plate.layout.raw.Ct.values'!R13:T13) -> 38.88 | M13: =AVERAGE(J13:L13) -> 38.507778 | N13: =M13-$M$14 -> 17.044444 | O13: =2^(-N13) -> 7.3979427e-06 | P13: =LOG(O13) -> -5.130889
A14: RPL47A | B14: M | C14: =AVERAGE('plate.layout.raw.Ct.values'!C14:E14) -> 23.206667 | D14: =AVERAGE('plate.layout.raw.Ct.values'!F14:H14) -> 23.263333 | E14: =AVERAGE('plate.layout.raw.Ct.values'!I14:K14) -> 22.543333 | F14: =AVERAGE(C14:E14) -> 23.004444 | G14: =F14-$F$14 -> 0 | H14: =2^(-G14) -> 1 | I14: =LOG(H14) -> 0 | J14: =AVERAGE('plate.layout.raw.Ct.values'!L14:N14) -> 19.783333 | K14: =AVERAGE('plate.layout.raw.Ct.values'!O14:Q14) -> 21.463333 | L14: =AVERAGE('plate.layout.raw.Ct.values'!R14:T14) -> 23.143333 | M14: =AVERAGE(J14:L14) -> 21.463333 | N14: =M14-$M$14 -> 0 | O14: =2^(-N14) -> 1 | P14: =LOG(O14) -> 0
I18: 0.25620997 | J18: -0.40772841 | M18: 0.25620997 | N18: -0.40772841
I19: 0.23112414 | J19: -3.6889554 | M19: 0.23112414 | N19: -3.6889554
I20: -2.1874846 | J20: -3.8244189 | M20: -2.1874846 | N20: -3.8244189
I21: -0.98035435 | J21: -2.4968766 | M21: -0.98035435 | N21: -2.4968766
I22: -1.535253 | J22: -2.2403321 | M22: -1.535253 | N22: -2.2403321
I23: -2.6213023 | J23: -4.1879962 | M23: -2.6213023 | N23: -4.1879962
I24: -0.79772949 | J24: -2.009208 | M24: -0.79772949 | N24: -2.009208
I25: -2.5396897 | J25: -3.4350867 | M25: -2.5396897 | N25: -3.4350867
I26: -2.3624165 | J26: -3.3324021 | M26: -2.3624165 | N26: -3.3324021
I27: -1.791463 | J27: -5.130889 | M27: -1.791463 | N27: -5.130889
I28: 0 | J28: 0
